<sdf version='1.7'>
  <world name='default'>
    <light name='sun' type='directional'>
      <cast_shadows>1</cast_shadows>
      <pose>0 0 10 0 -0 0</pose>
      <diffuse>0.8 0.8 0.8 1</diffuse>
      <specular>0.2 0.2 0.2 1</specular>
      <attenuation>
        <range>1000</range>
        <constant>0.9</constant>
        <linear>0.01</linear>
        <quadratic>0.001</quadratic>
      </attenuation>
      <direction>-0.5 0.1 -0.9</direction>
      <spot>
        <inner_angle>0</inner_angle>
        <outer_angle>0</outer_angle>
        <falloff>0</falloff>
      </spot>
    </light>
    <model name='ground_plane'>
      <static>1</static>
      <link name='link'>
        <collision name='collision'>
          <geometry>
            <plane>
              <normal>0 0 1</normal>
              <size>100 100</size>
            </plane>
          </geometry>
          <surface>
            <friction>
              <ode>
                <mu>100</mu>
                <mu2>50</mu2>
              </ode>
              <torsional>
                <ode/>
              </torsional>
            </friction>
            <contact>
              <ode/>
            </contact>
            <bounce/>
          </surface>
          <max_contacts>10</max_contacts>
        </collision>
        <visual name='visual'>
          <cast_shadows>0</cast_shadows>
          <geometry>
            <plane>
              <normal>0 0 1</normal>
              <size>100 100</size>
            </plane>
          </geometry>
          <material>
            <script>
              <uri>file://media/materials/scripts/gazebo.material</uri>
              <name>Gazebo/Grey</name>
            </script>
          </material>
        </visual>
        <self_collide>0</self_collide>
        <enable_wind>0</enable_wind>
        <kinematic>0</kinematic>
      </link>
    </model>
    <gravity>0 0 -9.8</gravity>
    <magnetic_field>6e-06 2.3e-05 -4.2e-05</magnetic_field>
    <atmosphere type='adiabatic'/>
    <physics type='ode'>
      <max_step_size>0.001</max_step_size>
      <real_time_factor>1</real_time_factor>
      <real_time_update_rate>1000</real_time_update_rate>
    </physics>
    <scene>
      <ambient>0.4 0.4 0.4 1</ambient>
      <background>0.7 0.7 0.7 1</background>
      <shadows>1</shadows>
    </scene>
    <audio>
      <device>default</device>
    </audio>
    <wind/>
    <spherical_coordinates>
      <surface_model>EARTH_WGS84</surface_model>
      <latitude_deg>0</latitude_deg>
      <longitude_deg>0</longitude_deg>
      <elevation>0</elevation>
      <heading_deg>0</heading_deg>
    </spherical_coordinates>
    <model name='my_rover'>
      <link name='base_footprint'>
        <inertial>
          <pose>0.001088 0 0.047186 0 -0 0</pose>
          <mass>10.11</mass>
          <inertia>
            <ixx>0.0578789</ixx>
            <ixy>0</ixy>
            <ixz>-0.00218595</ixz>
            <iyy>0.0995919</iyy>
            <iyz>0</iyz>
            <izz>0.0938779</izz>
          </inertia>
        </inertial>
        <collision name='base_footprint_fixed_joint_lump__base_link_collision'>
          <pose>0 0 0.09 0 -0 0</pose>
          <geometry>
            <box>
              <size>0.4 0.25 0.13</size>
            </box>
          </geometry>
          <surface>
            <contact>
              <ode/>
            </contact>
            <friction>
              <ode/>
              <torsional>
                <ode/>
              </torsional>
            </friction>
            <bounce/>
          </surface>
          <max_contacts>10</max_contacts>
        </collision>
        <visual name='base_footprint_visual'>
          <pose>0 0 0 0 -0 0</pose>
          <geometry>
            <box>
              <size>0.001 0.001 0.001</size>
            </box>
          </geometry>
        </visual>
        <visual name='base_footprint_fixed_joint_lump__base_link_visual_1'>
          <pose>0 0 0.09 0 -0 0</pose>
          <geometry>
            <box>
              <size>0.4 0.25 0.13</size>
            </box>
          </geometry>
          <material>
            <script>
              <name>Gazebo/White</name>
              <uri>file://media/materials/scripts/gazebo.material</uri>
            </script>
          </material>
        </visual>
        <visual name='base_footprint_fixed_joint_lump__laserholder_link_visual_2'>
          <pose>0.1 0 0.205 0 -0 0</pose>
          <geometry>
            <cylinder>
              <length>0.1</length>
              <radius>0.02</radius>
            </cylinder>
          </geometry>
        </visual>
        <visual name='base_footprint_fixed_joint_lump__scan_link_visual_3'>
          <pose>0.1 0 0.255 0 -0 0</pose>
          <geometry>
            <cylinder>
              <length>0.04</length>
              <radius>0.04</radius>
            </cylinder>
          </geometry>
        </visual>
        <sensor name='lidar' type='ray'>
          <always_on>1</always_on>
          <visualize>1</visualize>
          <update_rate>10</update_rate>
          <ray>
            <scan>
              <horizontal>
                <samples>360</samples>
                <resolution>1</resolution>
                <min_angle>0</min_angle>
                <max_angle>6.28</max_angle>
              </horizontal>
              <vertical>
                <samples>1</samples>
                <min_angle>0</min_angle>
                <max_angle>0</max_angle>
              </vertical>
            </scan>
            <range>
              <min>0.12</min>
              <max>10</max>
              <resolution>0.02</resolution>
            </range>
            <noise>
              <type>gaussian</type>
              <mean>0</mean>
              <stddev>0.01</stddev>
            </noise>
          </ray>
          <plugin name='scan' filename='libgazebo_ros_ray_sensor.so'>
            <ros>
              <remapping>~/out:=scan</remapping>
            </ros>
            <output_type>sensor_msgs/LaserScan</output_type>
            <frame_name>scan_link</frame_name>
          </plugin>
          <pose>0.1 0 0.255 0 -0 0</pose>
        </sensor>
        <self_collide>0</self_collide>
        <enable_wind>0</enable_wind>
        <kinematic>0</kinematic>
      </link>
      <joint name='joint_FL' type='revolute'>
        <pose relative_to='base_footprint'>0.15 0.16 0.07 -1.5708 0 0</pose>
        <parent>base_footprint</parent>
        <child>wheel_FL</child>
        <axis>
          <xyz>0 0 1</xyz>
          <limit>
            <lower>-1e+16</lower>
            <upper>1e+16</upper>
          </limit>
          <dynamics>
            <spring_reference>0</spring_reference>
            <spring_stiffness>0</spring_stiffness>
          </dynamics>
        </axis>
      </joint>
      <link name='wheel_FL'>
        <pose relative_to='joint_FL'>0 0 0 0 -0 0</pose>
        <inertial>
          <pose>0 0 0 0 -0 0</pose>
          <mass>0.5</mass>
          <inertia>
            <ixx>0.00111667</ixx>
            <ixy>0</ixy>
            <ixz>0</ixz>
            <iyy>0.00111667</iyy>
            <iyz>0</iyz>
            <izz>0.002025</izz>
          </inertia>
        </inertial>
        <collision name='wheel_FL_collision'>
          <pose>0 0 0 0 -0 0</pose>
          <geometry>
            <cylinder>
              <length>0.05</length>
              <radius>0.09</radius>
            </cylinder>
          </geometry>
          <surface>
            <contact>
              <ode/>
            </contact>
            <friction>
              <ode>
                <mu>0.001</mu>
                <mu2>0.001</mu2>
              </ode>
              <torsional>
                <ode/>
              </torsional>
            </friction>
            <bounce/>
          </surface>
          <max_contacts>10</max_contacts>
        </collision>
        <visual name='wheel_FL_visual'>
          <pose>0 0 0 0 -0 0</pose>
          <geometry>
            <cylinder>
              <length>0.05</length>
              <radius>0.09</radius>
            </cylinder>
          </geometry>
          <material>
            <script>
              <name>Gazebo/Black</name>
              <uri>file://media/materials/scripts/gazebo.material</uri>
            </script>
          </material>
        </visual>
        <self_collide>0</self_collide>
        <enable_wind>0</enable_wind>
        <kinematic>0</kinematic>
      </link>
      <joint name='joint_FR' type='revolute'>
        <pose relative_to='base_footprint'>0.15 -0.16 0.07 -1.5708 0 0</pose>
        <parent>base_footprint</parent>
        <child>wheel_FR</child>
        <axis>
          <xyz>0 0 1</xyz>
          <limit>
            <lower>-1e+16</lower>
            <upper>1e+16</upper>
          </limit>
          <dynamics>
            <spring_reference>0</spring_reference>
            <spring_stiffness>0</spring_stiffness>
          </dynamics>
        </axis>
      </joint>
      <link name='wheel_FR'>
        <pose relative_to='joint_FR'>0 0 0 0 -0 0</pose>
        <inertial>
          <pose>0 0 0 0 -0 0</pose>
          <mass>0.5</mass>
          <inertia>
            <ixx>0.00111667</ixx>
            <ixy>0</ixy>
            <ixz>0</ixz>
            <iyy>0.00111667</iyy>
            <iyz>0</iyz>
            <izz>0.002025</izz>
          </inertia>
        </inertial>
        <collision name='wheel_FR_collision'>
          <pose>0 0 0 0 -0 0</pose>
          <geometry>
            <cylinder>
              <length>0.05</length>
              <radius>0.09</radius>
            </cylinder>
          </geometry>
          <surface>
            <contact>
              <ode/>
            </contact>
            <friction>
              <ode>
                <mu>0.001</mu>
                <mu2>0.001</mu2>
              </ode>
              <torsional>
                <ode/>
              </torsional>
            </friction>
            <bounce/>
          </surface>
          <max_contacts>10</max_contacts>
        </collision>
        <visual name='wheel_FR_visual'>
          <pose>0 0 0 0 -0 0</pose>
          <geometry>
            <cylinder>
              <length>0.05</length>
              <radius>0.09</radius>
            </cylinder>
          </geometry>
          <material>
            <script>
              <name>Gazebo/Black</name>
              <uri>file://media/materials/scripts/gazebo.material</uri>
            </script>
          </material>
        </visual>
        <self_collide>0</self_collide>
        <enable_wind>0</enable_wind>
        <kinematic>0</kinematic>
      </link>
      <joint name='joint_RL' type='revolute'>
        <pose relative_to='base_footprint'>-0.15 0.16 0.07 -1.5708 0 0</pose>
        <parent>base_footprint</parent>
        <child>wheel_RL</child>
        <axis>
          <xyz>0 0 1</xyz>
          <limit>
            <lower>-1e+16</lower>
            <upper>1e+16</upper>
          </limit>
          <dynamics>
            <spring_reference>0</spring_reference>
            <spring_stiffness>0</spring_stiffness>
          </dynamics>
        </axis>
      </joint>
      <link name='wheel_RL'>
        <pose relative_to='joint_RL'>0 0 0 0 -0 0</pose>
        <inertial>
          <pose>0 0 0 0 -0 0</pose>
          <mass>0.5</mass>
          <inertia>
            <ixx>0.00111667</ixx>
            <ixy>0</ixy>
            <ixz>0</ixz>
            <iyy>0.00111667</iyy>
            <iyz>0</iyz>
            <izz>0.002025</izz>
          </inertia>
        </inertial>
        <collision name='wheel_RL_collision'>
          <pose>0 0 0 0 -0 0</pose>
          <geometry>
            <cylinder>
              <length>0.05</length>
              <radius>0.09</radius>
            </cylinder>
          </geometry>
          <surface>
            <contact>
              <ode/>
            </contact>
            <friction>
              <ode/>
              <torsional>
                <ode/>
              </torsional>
            </friction>
            <bounce/>
          </surface>
          <max_contacts>10</max_contacts>
        </collision>
        <visual name='wheel_RL_visual'>
          <pose>0 0 0 0 -0 0</pose>
          <geometry>
            <cylinder>
              <length>0.05</length>
              <radius>0.09</radius>
            </cylinder>
          </geometry>
          <material>
            <script>
              <name>Gazebo/Black</name>
              <uri>file://media/materials/scripts/gazebo.material</uri>
            </script>
          </material>
        </visual>
        <self_collide>0</self_collide>
        <enable_wind>0</enable_wind>
        <kinematic>0</kinematic>
      </link>
      <joint name='joint_RR' type='revolute'>
        <pose relative_to='base_footprint'>-0.15 -0.16 0.07 -1.5708 0 0</pose>
        <parent>base_footprint</parent>
        <child>wheel_RR</child>
        <axis>
          <xyz>0 0 1</xyz>
          <limit>
            <lower>-1e+16</lower>
            <upper>1e+16</upper>
          </limit>
          <dynamics>
            <spring_reference>0</spring_reference>
            <spring_stiffness>0</spring_stiffness>
          </dynamics>
        </axis>
      </joint>
      <link name='wheel_RR'>
        <pose relative_to='joint_RR'>0 0 0 0 -0 0</pose>
        <inertial>
          <pose>0 0 0 0 -0 0</pose>
          <mass>0.5</mass>
          <inertia>
            <ixx>0.00111667</ixx>
            <ixy>0</ixy>
            <ixz>0</ixz>
            <iyy>0.00111667</iyy>
            <iyz>0</iyz>
            <izz>0.002025</izz>
          </inertia>
        </inertial>
        <collision name='wheel_RR_collision'>
          <pose>0 0 0 0 -0 0</pose>
          <geometry>
            <cylinder>
              <length>0.05</length>
              <radius>0.09</radius>
            </cylinder>
          </geometry>
          <surface>
            <contact>
              <ode/>
            </contact>
            <friction>
              <ode/>
              <torsional>
                <ode/>
              </torsional>
            </friction>
            <bounce/>
          </surface>
          <max_contacts>10</max_contacts>
        </collision>
        <visual name='wheel_RR_visual'>
          <pose>0 0 0 0 -0 0</pose>
          <geometry>
            <cylinder>
              <length>0.05</length>
              <radius>0.09</radius>
            </cylinder>
          </geometry>
          <material>
            <script>
              <name>Gazebo/Black</name>
              <uri>file://media/materials/scripts/gazebo.material</uri>
            </script>
          </material>
        </visual>
        <self_collide>0</self_collide>
        <enable_wind>0</enable_wind>
        <kinematic>0</kinematic>
      </link>
      <plugin name='diff_drive' filename='libgazebo_ros_diff_drive.so'>
        <ros>
          <namespace>/</namespace>
          <remapping>cmd_vel:=cmd_vel</remapping>
          <remapping>odom:=odom</remapping>
        </ros>
        <left_joint>joint_RL</left_joint>
        <right_joint>joint_RR</right_joint>
        <wheel_separation>0.32</wheel_separation>
        <wheel_diameter>0.18</wheel_diameter>
        <max_wheel_torque>200</max_wheel_torque>
        <max_wheel_acceleration>5.0</max_wheel_acceleration>
        <publish_odom>1</publish_odom>
        <publish_odom_tf>1</publish_odom_tf>
        <publish_wheel_tf>1</publish_wheel_tf>
        <odometry_frame>odom</odometry_frame>
        <robot_base_frame>base_footprint</robot_base_frame>
      </plugin>
      <static>0</static>
      <plugin name='joint_state_publisher' filename='libgazebo_ros_joint_state_publisher.so'>
        <ros>
          <remapping>~/out:=joint_states</remapping>
        </ros>
        <update_rate>30</update_rate>
        <joint_name>joint_FL</joint_name>
        <joint_name>joint_FR</joint_name>
        <joint_name>joint_RL</joint_name>
        <joint_name>joint_RR</joint_name>
      </plugin>
      <pose>0 0 0 0 -0 0</pose>
    </model>
    <model name='Untitled'>
      <pose>1.5 -2 0 0 -0 0</pose>
      <link name='Wall_0'>
        <collision name='Wall_0_Collision'>
          <geometry>
            <box>
              <size>10.15 0.15 2.5</size>
            </box>
          </geometry>
          <pose>0 0 1.25 0 -0 0</pose>
          <max_contacts>10</max_contacts>
          <surface>
            <contact>
              <ode/>
            </contact>
            <bounce/>
            <friction>
              <torsional>
                <ode/>
              </torsional>
              <ode/>
            </friction>
          </surface>
        </collision>
        <visual name='Wall_0_Visual'>
          <pose>0 0 1.25 0 -0 0</pose>
          <geometry>
            <box>
              <size>10.15 0.15 2.5</size>
            </box>
          </geometry>
          <material>
            <script>
              <uri>file://media/materials/scripts/gazebo.material</uri>
              <name>Gazebo/Grey</name>
            </script>
            <ambient>1 1 1 1</ambient>
          </material>
          <meta>
            <layer>0</layer>
          </meta>
        </visual>
        <pose>-1.5 1 0 0 -0 0</pose>
        <self_collide>0</self_collide>
        <enable_wind>0</enable_wind>
        <kinematic>0</kinematic>
      </link>
      <link name='Wall_10'>
        <collision name='Wall_10_Collision'>
          <geometry>
            <box>
              <size>8.15 0.15 2.5</size>
            </box>
          </geometry>
          <pose>0 0 1.25 0 -0 0</pose>
          <max_contacts>10</max_contacts>
          <surface>
            <contact>
              <ode/>
            </contact>
            <bounce/>
            <friction>
              <torsional>
                <ode/>
              </torsional>
              <ode/>
            </friction>
          </surface>
        </collision>
        <visual name='Wall_10_Visual'>
          <pose>0 0 1.25 0 -0 0</pose>
          <geometry>
            <box>
              <size>8.15 0.15 2.5</size>
            </box>
          </geometry>
          <material>
            <script>
              <uri>file://media/materials/scripts/gazebo.material</uri>
              <name>Gazebo/Grey</name>
            </script>
            <ambient>1 1 1 1</ambient>
          </material>
          <meta>
            <layer>0</layer>
          </meta>
        </visual>
        <pose>8.5 0 0 0 -0 1.5708</pose>
        <self_collide>0</self_collide>
        <enable_wind>0</enable_wind>
        <kinematic>0</kinematic>
      </link>
      <link name='Wall_11'>
        <collision name='Wall_11_Collision'>
          <geometry>
            <box>
              <size>17.15 0.15 2.5</size>
            </box>
          </geometry>
          <pose>0 0 1.25 0 -0 0</pose>
          <max_contacts>10</max_contacts>
          <surface>
            <contact>
              <ode/>
            </contact>
            <bounce/>
            <friction>
              <torsional>
                <ode/>
              </torsional>
              <ode/>
            </friction>
          </surface>
        </collision>
        <visual name='Wall_11_Visual'>
          <pose>0 0 1.25 0 -0 0</pose>
          <geometry>
            <box>
              <size>17.15 0.15 2.5</size>
            </box>
          </geometry>
          <material>
            <script>
              <uri>file://media/materials/scripts/gazebo.material</uri>
              <name>Gazebo/Grey</name>
            </script>
            <ambient>1 1 1 1</ambient>
          </material>
          <meta>
            <layer>0</layer>
          </meta>
        </visual>
        <pose>-0 4 0 0 -0 3.14159</pose>
        <self_collide>0</self_collide>
        <enable_wind>0</enable_wind>
        <kinematic>0</kinematic>
      </link>
      <link name='Wall_2'>
        <collision name='Wall_2_Collision'>
          <geometry>
            <box>
              <size>1.65 0.15 2.5</size>
            </box>
          </geometry>
          <pose>0 0 1.25 0 -0 0</pose>
          <max_contacts>10</max_contacts>
          <surface>
            <contact>
              <ode/>
            </contact>
            <bounce/>
            <friction>
              <torsional>
                <ode/>
              </torsional>
              <ode/>
            </friction>
          </surface>
        </collision>
        <visual name='Wall_2_Visual'>
          <pose>0 0 1.25 0 -0 0</pose>
          <geometry>
            <box>
              <size>1.65 0.15 2.5</size>
            </box>
          </geometry>
          <material>
            <script>
              <uri>file://media/materials/scripts/gazebo.material</uri>
              <name>Gazebo/Grey</name>
            </script>
            <ambient>1 1 1 1</ambient>
          </material>
          <meta>
            <layer>0</layer>
          </meta>
        </visual>
        <pose>3.5 0.25 0 0 -0 -1.5708</pose>
        <self_collide>0</self_collide>
        <enable_wind>0</enable_wind>
        <kinematic>0</kinematic>
      </link>
      <link name='Wall_3'>
        <collision name='Wall_3_Collision'>
          <geometry>
            <box>
              <size>3.15 0.15 2.5</size>
            </box>
          </geometry>
          <pose>0 0 1.25 0 -0 0</pose>
          <max_contacts>10</max_contacts>
          <surface>
            <contact>
              <ode/>
            </contact>
            <bounce/>
            <friction>
              <torsional>
                <ode/>
              </torsional>
              <ode/>
            </friction>
          </surface>
        </collision>
        <visual name='Wall_3_Visual'>
          <pose>0 0 1.25 0 -0 0</pose>
          <geometry>
            <box>
              <size>3.15 0.15 2.5</size>
            </box>
          </geometry>
          <material>
            <script>
              <uri>file://media/materials/scripts/gazebo.material</uri>
              <name>Gazebo/Grey</name>
            </script>
            <ambient>1 1 1 1</ambient>
          </material>
          <meta>
            <layer>0</layer>
          </meta>
        </visual>
        <pose>2 -0.5 0 0 -0 3.14159</pose>
        <self_collide>0</self_collide>
        <enable_wind>0</enable_wind>
        <kinematic>0</kinematic>
      </link>
      <link name='Wall_4'>
        <collision name='Wall_4_Collision'>
          <geometry>
            <box>
              <size>1.65 0.15 2.5</size>
            </box>
          </geometry>
          <pose>0 0 1.25 0 -0 0</pose>
          <max_contacts>10</max_contacts>
          <surface>
            <contact>
              <ode/>
            </contact>
            <bounce/>
            <friction>
              <torsional>
                <ode/>
              </torsional>
              <ode/>
            </friction>
          </surface>
        </collision>
        <visual name='Wall_4_Visual'>
          <pose>0 0 1.25 0 -0 0</pose>
          <geometry>
            <box>
              <size>1.65 0.15 2.5</size>
            </box>
          </geometry>
          <material>
            <script>
              <uri>file://media/materials/scripts/gazebo.material</uri>
              <name>Gazebo/Grey</name>
            </script>
            <ambient>1 1 1 1</ambient>
          </material>
          <meta>
            <layer>0</layer>
          </meta>
        </visual>
        <pose>0.5 -1.25 0 0 -0 -1.5708</pose>
        <self_collide>0</self_collide>
        <enable_wind>0</enable_wind>
        <kinematic>0</kinematic>
      </link>
      <link name='Wall_5'>
        <collision name='Wall_5_Collision'>
          <geometry>
            <box>
              <size>7.15 0.15 2.5</size>
            </box>
          </geometry>
          <pose>0 0 1.25 0 -0 0</pose>
          <max_contacts>10</max_contacts>
          <surface>
            <contact>
              <ode/>
            </contact>
            <bounce/>
            <friction>
              <torsional>
                <ode/>
              </torsional>
              <ode/>
            </friction>
          </surface>
        </collision>
        <visual name='Wall_5_Visual'>
          <pose>0 0 1.25 0 -0 0</pose>
          <geometry>
            <box>
              <size>7.15 0.15 2.5</size>
            </box>
          </geometry>
          <material>
            <script>
              <uri>file://media/materials/scripts/gazebo.material</uri>
              <name>Gazebo/Grey</name>
            </script>
            <ambient>1 1 1 1</ambient>
          </material>
          <meta>
            <layer>0</layer>
          </meta>
        </visual>
        <pose>-3 -2 0 0 -0 3.14159</pose>
        <self_collide>0</self_collide>
        <enable_wind>0</enable_wind>
        <kinematic>0</kinematic>
      </link>
      <link name='Wall_6'>
        <collision name='Wall_6_Collision'>
          <geometry>
            <box>
              <size>3.15 0.15 2.5</size>
            </box>
          </geometry>
          <pose>0 0 1.25 0 -0 0</pose>
          <max_contacts>10</max_contacts>
          <surface>
            <contact>
              <ode/>
            </contact>
            <bounce/>
            <friction>
              <torsional>
                <ode/>
              </torsional>
              <ode/>
            </friction>
          </surface>
        </collision>
        <visual name='Wall_6_Visual'>
          <pose>0 0 1.25 0 -0 0</pose>
          <geometry>
            <box>
              <size>3.15 0.15 2.5</size>
            </box>
          </geometry>
          <material>
            <script>
              <uri>file://media/materials/scripts/gazebo.material</uri>
              <name>Gazebo/Grey</name>
            </script>
            <ambient>1 1 1 1</ambient>
          </material>
          <meta>
            <layer>0</layer>
          </meta>
        </visual>
        <pose>-6.5 -0.5 0 0 -0 1.5708</pose>
        <self_collide>0</self_collide>
        <enable_wind>0</enable_wind>
        <kinematic>0</kinematic>
      </link>
      <link name='Wall_8'>
        <collision name='Wall_8_Collision'>
          <geometry>
            <box>
              <size>8.15 0.15 2.5</size>
            </box>
          </geometry>
          <pose>0 0 1.25 0 -0 0</pose>
          <max_contacts>10</max_contacts>
          <surface>
            <contact>
              <ode/>
            </contact>
            <bounce/>
            <friction>
              <torsional>
                <ode/>
              </torsional>
              <ode/>
            </friction>
          </surface>
        </collision>
        <visual name='Wall_8_Visual'>
          <pose>0 0 1.25 0 -0 0</pose>
          <geometry>
            <box>
              <size>8.15 0.15 2.5</size>
            </box>
          </geometry>
          <material>
            <script>
              <uri>file://media/materials/scripts/gazebo.material</uri>
              <name>Gazebo/Grey</name>
            </script>
            <ambient>1 1 1 1</ambient>
          </material>
          <meta>
            <layer>0</layer>
          </meta>
        </visual>
        <pose>-8.5 0 0 0 -0 -1.5708</pose>
        <self_collide>0</self_collide>
        <enable_wind>0</enable_wind>
        <kinematic>0</kinematic>
      </link>
      <link name='Wall_9'>
        <collision name='Wall_9_Collision'>
          <geometry>
            <box>
              <size>17.15 0.15 2.5</size>
            </box>
          </geometry>
          <pose>0 0 1.25 0 -0 0</pose>
          <max_contacts>10</max_contacts>
          <surface>
            <contact>
              <ode/>
            </contact>
            <bounce/>
            <friction>
              <torsional>
                <ode/>
              </torsional>
              <ode/>
            </friction>
          </surface>
        </collision>
        <visual name='Wall_9_Visual'>
          <pose>0 0 1.25 0 -0 0</pose>
          <geometry>
            <box>
              <size>17.15 0.15 2.5</size>
            </box>
          </geometry>
          <material>
            <script>
              <uri>file://media/materials/scripts/gazebo.material</uri>
              <name>Gazebo/Grey</name>
            </script>
            <ambient>1 1 1 1</ambient>
          </material>
          <meta>
            <layer>0</layer>
          </meta>
        </visual>
        <pose>-0 -4 0 0 -0 0</pose>
        <self_collide>0</self_collide>
        <enable_wind>0</enable_wind>
        <kinematic>0</kinematic>
      </link>
      <static>1</static>
    </model>
    <model name='unit_box'>
      <pose>9.31573 -5.27129 0.5 0 -0 0</pose>
      <link name='link'>
        <inertial>
          <mass>1</mass>
          <inertia>
            <ixx>0.166667</ixx>
            <ixy>0</ixy>
            <ixz>0</ixz>
            <iyy>0.166667</iyy>
            <iyz>0</iyz>
            <izz>0.166667</izz>
          </inertia>
          <pose>0 0 0 0 -0 0</pose>
        </inertial>
        <collision name='collision'>
          <geometry>
            <box>
              <size>1 1 1</size>
            </box>
          </geometry>
          <max_contacts>10</max_contacts>
          <surface>
            <contact>
              <ode/>
            </contact>
            <bounce/>
            <friction>
              <torsional>
                <ode/>
              </torsional>
              <ode/>
            </friction>
          </surface>
        </collision>
        <visual name='visual'>
          <geometry>
            <box>
              <size>1 1 1</size>
            </box>
          </geometry>
          <material>
            <script>
              <name>Gazebo/Grey</name>
              <uri>file://media/materials/scripts/gazebo.material</uri>
            </script>
          </material>
        </visual>
        <self_collide>0</self_collide>
        <enable_wind>0</enable_wind>
        <kinematic>0</kinematic>
      </link>
    </model>
    <state world_name='default'>
      <sim_time>81 199000000</sim_time>
      <real_time>81 589810603</real_time>
      <wall_time>1767613078 149553784</wall_time>
      <iterations>81199</iterations>
      <model name='Untitled'>
        <pose>1.5 -2 0 0 -0 0</pose>
        <scale>1 1 1</scale>
        <link name='Wall_0'>
          <pose>0 -1 0 0 -0 0</pose>
          <velocity>0 0 0 0 -0 0</velocity>
          <acceleration>0 0 0 0 -0 0</acceleration>
          <wrench>0 0 0 0 -0 0</wrench>
        </link>
        <link name='Wall_10'>
          <pose>10 -2 0 0 -0 1.5708</pose>
          <velocity>0 0 0 0 -0 0</velocity>
          <acceleration>0 0 0 0 -0 0</acceleration>
          <wrench>0 0 0 0 -0 0</wrench>
        </link>
        <link name='Wall_11'>
          <pose>1.5 2 0 0 -0 3.14159</pose>
          <velocity>0 0 0 0 -0 0</velocity>
          <acceleration>0 0 0 0 -0 0</acceleration>
          <wrench>0 0 0 0 -0 0</wrench>
        </link>
        <link name='Wall_2'>
          <pose>5 -1.75 0 0 0 -1.5708</pose>
          <velocity>0 0 0 0 -0 0</velocity>
          <acceleration>0 0 0 0 -0 0</acceleration>
          <wrench>0 0 0 0 -0 0</wrench>
        </link>
        <link name='Wall_3'>
          <pose>3.5 -2.5 0 0 -0 3.14159</pose>
          <velocity>0 0 0 0 -0 0</velocity>
          <acceleration>0 0 0 0 -0 0</acceleration>
          <wrench>0 0 0 0 -0 0</wrench>
        </link>
        <link name='Wall_4'>
          <pose>2 -3.25 0 0 0 -1.5708</pose>
          <velocity>0 0 0 0 -0 0</velocity>
          <acceleration>0 0 0 0 -0 0</acceleration>
          <wrench>0 0 0 0 -0 0</wrench>
        </link>
        <link name='Wall_5'>
          <pose>-1.5 -4 0 0 -0 3.14159</pose>
          <velocity>0 0 0 0 -0 0</velocity>
          <acceleration>0 0 0 0 -0 0</acceleration>
          <wrench>0 0 0 0 -0 0</wrench>
        </link>
        <link name='Wall_6'>
          <pose>-5 -2.5 0 0 -0 1.5708</pose>
          <velocity>0 0 0 0 -0 0</velocity>
          <acceleration>0 0 0 0 -0 0</acceleration>
          <wrench>0 0 0 0 -0 0</wrench>
        </link>
        <link name='Wall_8'>
          <pose>-7 -2 0 0 0 -1.5708</pose>
          <velocity>0 0 0 0 -0 0</velocity>
          <acceleration>0 0 0 0 -0 0</acceleration>
          <wrench>0 0 0 0 -0 0</wrench>
        </link>
        <link name='Wall_9'>
          <pose>1.5 -6 0 0 -0 0</pose>
          <velocity>0 0 0 0 -0 0</velocity>
          <acceleration>0 0 0 0 -0 0</acceleration>
          <wrench>0 0 0 0 -0 0</wrench>
        </link>
      </model>
      <model name='ground_plane'>
        <pose>0 0 0 0 -0 0</pose>
        <scale>1 1 1</scale>
        <link name='link'>
          <pose>0 0 0 0 -0 0</pose>
          <velocity>0 0 0 0 -0 0</velocity>
          <acceleration>0 0 0 0 -0 0</acceleration>
          <wrench>0 0 0 0 -0 0</wrench>
        </link>
      </model>
      <model name='my_rover'>
        <pose>0.179345 0.041436 0.019995 -0 -3.1e-05 0.184574</pose>
        <scale>1 1 1</scale>
        <link name='base_footprint'>
          <pose>0.179345 0.041436 0.019995 -0 -3.1e-05 0.184574</pose>
          <velocity>0.003236 0.000883 -0.004728 0.005883 -0.031791 0.002586</velocity>
          <acceleration>-0.13078 -0.017863 -9.80391 -0.01046 0.354761 -0.024708</acceleration>
          <wrench>-1.32219 -0.180598 -99.1175 0 -0 0</wrench>
        </link>
        <link name='wheel_FL'>
          <pose>0.297431 0.226247 0.09 -1.5708 0.588714 0.184572</pose>
          <velocity>0.000534 0.000776 7.7e-05 -0.002157 0.008662 0.002586</velocity>
          <acceleration>-0.155391 -0.021898 -9.95287 0.647041 0.1208 -0.982767</acceleration>
          <wrench>-0.077695 -0.010949 -4.97643 0 -0 0</wrench>
        </link>
        <link name='wheel_FR'>
          <pose>0.35616 -0.088318 0.09 -1.57081 1.40815 0.184563</pose>
          <velocity>0.001346 0.000927 8.2e-05 -0.003846 0.017816 0.002579</velocity>
          <acceleration>-0.167905 -0.029021 -9.94598 0.538204 0.10048 -1.07908</acceleration>
          <wrench>-0.083952 -0.01451 -4.97299 0 -0 0</wrench>
        </link>
        <link name='wheel_RL'>
          <pose>0.002525 0.171188 0.089991 -1.5708 0.423774 0.1846</pose>
          <velocity>0.001016 9.1e-05 -0.009567 0.006233 -0.031725 -0.004641</velocity>
          <acceleration>1.28511 0.196394 -9.62484 2.08543 -1.36411 -2.52541</acceleration>
          <wrench>0.642557 0.098197 -4.81242 0 -0 0</wrench>
        </link>
        <link name='wheel_RR'>
          <pose>0.061253 -0.143377 0.089991 -1.5708 0.725072 0.184605</pose>
          <velocity>0.002039 0.000272 -0.009559 0.006258 -0.031721 -0.006314</velocity>
          <acceleration>1.68255 0.215722 -9.59733 -3.09567 1.47159 -2.35964</acceleration>
          <wrench>0.841277 0.107861 -4.79867 0 -0 0</wrench>
        </link>
      </model>
      <model name='unit_box'>
        <pose>9.42501 -5.425 0.5 0 0 -3e-06</pose>
        <scale>1 1 1</scale>
        <link name='link'>
          <pose>9.42501 -5.425 0.5 0 0 -3e-06</pose>
          <velocity>0 0 0 0 -0 0</velocity>
          <acceleration>0 0 0 0 -0 0</acceleration>
          <wrench>0 0 0 0 -0 0</wrench>
        </link>
      </model>
      <light name='sun'>
        <pose>0 0 10 0 -0 0</pose>
      </light>
    </state>
    <gui fullscreen='0'>
      <camera name='user_camera'>
        <pose>1.96509 -12.822 25.053 0 1.2994 1.65678</pose>
        <view_controller>orbit</view_controller>
        <projection_type>perspective</projection_type>
      </camera>
    </gui>
  </world>
</sdf>
